I'm sorry, but an uncaught exception occurred.

While running game code:
  File "game/script.rpy", line 79, in script
    k "¡Me parece buena idea! de paso podria invitarte a algo."
Exception: Sayer 'K' is not defined.

-- Full Traceback ------------------------------------------------------------

Full traceback:
  File "game/script.rpy", line 79, in script
    k "¡Me parece buena idea! de paso podria invitarte a algo."
  File "C:\Users\Aura\Desktop\renpy-8.3.7-sdk\renpy\ast.py", line 2586, in execute
    Say.execute(self)
  File "C:\Users\Aura\Desktop\renpy-8.3.7-sdk\renpy\ast.py", line 583, in execute
    who = eval_who(self.who, self.who_fast)
  File "C:\Users\Aura\Desktop\renpy-8.3.7-sdk\renpy\ast.py", line 472, in eval_who
    raise Exception("Sayer '%s' is not defined." % who)
Exception: Sayer 'K' is not defined.

Windows-10-10.0.19045 AMD64
Ren'Py 8.3.7.25031702
The Last Day Forever 1.0
Fri Aug 22 12:23:45 2025
